<html>
	<header>
		<title>Training 2</title>
	</header>
	<body style=" margin:50px 150px">
		<h1 style=" text-align:center;"> Javascript  File 2  </h1>
		<h3 style=" text-align:center;"> Control flow and error handling  </h3>
		<div class="test">Testting</div>
		<script> 
			//Control flow and error handling
			//Block statement Example... if, for, switch  
			//Example
			var x=0;
			while(x!=10){
				x++;
				console.log(x);
				//statement 
			}
			
			var p = 1;
			{
			  var p = 2;
			}
			console.log(p); // outputs 2
			//Conditional statements
			//if...else
			
			// Classifying numbers into even, odd and prime numbers from 1 to 10  
			
			x = 0;
			while(x!=10){
				if(x%2 === 0){
					if(x === 2) console.log(x+" Number is Prime. ");
					console.log(x+" is even ");
				}else{
					if(x === 1) console.log(x+" Number is Prime. ");
					let i=2;
					while(i<x){						
						if(x%i==0) break;
						else i++;	
					}
					if(i == x) console.log(x+" Number is Prime. ");
					console.log(x+" is odd ");
				}
				x++;
			}
			
			if((x=10)) console.log(x);
	
			//Falsy values
			/*
			 The following values evaluate to false (also known as Falsy values):
				-)false
				-)undefined
				-)null
				-)0
				-)NaN
				-)the empty string ("")	
			*/
			//switch
			let l='a';
			
			switch(l){
				case 'a':
					console.log('A');
					break;
				case 'b':
					console.log('B');
					break;
				case 'c':
					console.log('C');
					break;
				case 'd':
					console.log('D');
					break;
				case 'e':
					console.log('E');
					break;
				default:
					console.log("Exit");
			}
			
			
			
			//Exception handling statements
			//throw statement
			//try...catch statement
			
			//try/catch/throw
			//Error objects
			
			//Exception types
			//throw statement
			//throws several exceptions of varying types: 
			/*
			throw "Error2";   // String type
			throw 42;         // Number type
			throw true;       // Boolean type
			throw {toString: function() { return "I'm an object!"; } };
			*/
			
			//Example 
			// Create an object type UserException
			function TrainingException(message) {
			    this.message = message+"...younis";
			    this.name = 'TrainingException';
			}

			// Make the exception convert to a pretty string when used as a string 
			// (e.g., by the error console)
			TrainingException.prototype.toString = function() {
				return `${this.name}: "${this.message}"`;
			}

			// Create an instance of the object type and throw it
			//throw new TrainingException('Value too high');
			
			
			//another Example
			
			function getMonthName(mo) {
				mo = mo - 1; // Adjust month number for array index (1 = Jan, 12 = Dec)
				let months = ['Jan', 'Feb', 'Mar', 'Apr', 'May', 'Jun', 'Jul',
								'Aug', 'Sep', 'Oct', 'Nov', 'Dec'];
				if(months[mo]){
					return months[mo];
				} else {
					throw 'InvalidMonthNo'; // throw keyword is used here
				}
			}

			try { // statements to try
				monthName = getMonthName(6); // jun
			//	monthName = getMonthName(myMonth); // function could throw exception
				console.log(monthName);
			}
			catch (e) {
				monthName = 'unknown';
				logMyErrors(e); // pass exception object to error handler (i.e. your own function)
			}
			finally {
				console.log("finish"); //Always executed after the try and catch blocks
			}	
			
			
			//another Example

			function f(){
				try{
					console.log(0);//0
					throw 'bogus';//Exception
				}
				catch(e){
					console.log(1);//1
					
					return true;    // this return statement is suspended
									// until finally block has completed
					console.log(2); // not reachable
				} 
				finally{
					console.log(3);//3 
					return false;   // overwrites the previous "return" //false
					console.log(4); // not reachable
				}
				  // "return false" is executed now  
				console.log(5);   // not reachable
			}
			console.log(f()); // 0, 1, 3, false
			

			//another Example try and catch

			function ff(){
				console.log("hhhh")
				try{
					throw 'bogus';
				}
				catch(e){
					console.log('caught inner "bogus"');
					//throw e; // this throw statement is suspended until 
							 // finally block has completed
				}
				finally{
					return false; // overwrites the previous "throw"
				}
				  // "return false" is executed now
			}

			try{
				console.log(ff());//caught inner "bogus" false
			} catch(e) {
   			    //this is never reached! 
			    //while f() executes, the `finally` block returns false, 
			    //which overwrites the `throw` inside the above `catch`
				console.log('caught outer "bogus"');
			}

			// OUTPUT
			// caught inner "bogus"
			// false

			


			
			//document.getElementById("test").innerHTML=a;
	
		</script>	
	</body>
</html>